В C++ оператор `throw` может использоваться без аргументов для повторного выбрасывания текущего исключения. Это полезно, когда вы хотите перехватить исключение в блоке `catch`, выполнить некоторую обработку, и затем передать это исключение выше по стеку вызовов.

### Синтаксис и использование

```cpp
try {
    // Код, который может выбросить исключение
    throw SomeException(); // Пример выброса исключения
} catch (const SomeException& e) {
    // Обработка исключения
    std::cerr << "Exception caught: " << e.what() << std::endl;
    throw; // Повторное выбрасывание текущего исключения
}
```

### Основные моменты

1. **Повторное выбрасывание**:
   - Использование `throw` без аргументов повторно выбрасывает текущее активное исключение. Это позволяет передать исключение на уровень выше в стеке вызовов.

2. **Использование в блоке `catch`**:
   - `throw;` без аргументов можно использовать только внутри блока `catch`. Это необходимо для передачи исключения в верхний уровень стека.

3. **Не выбрасывает новое исключение**:
   - `throw;` не создает новое исключение и не изменяет тип исключения. Оно просто повторно выбрасывает уже перехваченное исключение.

### Пример

Рассмотрим более полный пример, где мы используем `throw` без аргументов для повторного выбрасывания исключения:

```cpp
#include <iostream>
#include <stdexcept>

void func1() {
    throw std::runtime_error("Error in func1");
}

void func2() {
    try {
        func1();
    } catch (const std::runtime_error& e) {
        std::cerr << "Caught in func2: " << e.what() << std::endl;
        throw; // Повторное выбрасывание исключения
    }
}

int main() {
    try {
        func2();
    } catch (const std::runtime_error& e) {
        std::cerr << "Caught in main: " << e.what() << std::endl;
    }
    return 0;
}
```

### Вывод

```
Caught in func2: Error in func1
Caught in main: Error in func1
```

В этом примере исключение выбрасывается в `func1`, перехватывается в `func2`, где оно обрабатывается и затем повторно выбрасывается с помощью `throw;`, чтобы быть пойманным в `main`.

### Заключение

Оператор `throw` без аргументов используется для повторного выбрасывания текущего исключения, что позволяет передать его на более высокий уровень стека вызовов после выполнения некоторой обработки. Это полезно для реализации механизмов обработки ошибок, которые могут быть частично обработаны на одном уровне и затем переданы для дальнейшей обработки на более высоком уровне.